Workbook
Name AIP: MaterialData!$C$3:$F$3,MaterialData!$P$3
Name AIP: MaterialData!$C$3:$F$3,MaterialData!$P$3
Name AIP: MaterialData!$C$3:$F$3,MaterialData!$P$3
Name ConstructionType: MaterialData!$B$23:$B$25
Name ConstructionType: MaterialData!$B$23:$B$25
Name ConstructionType: MaterialData!$B$23:$B$25
Name Guidance_notes_FBHS: 'EV4.4 Guidance Notes'!$A$1
Name Guidance_notes_FBHS: #REF!
Name Guidance_notes_FBHS: 'T3.14 T3.6 Guidance Notes'!$A$1
Name Guidance_notes_FHB: #REF!
Name Guidance_notes_FHB: 'T3.12 T3.6 Guidance Notes'!$A$1
Name Guidance_notes_IA_and_AIP: #REF!
Name Guidance_notes_IA_and_AIP: 'T3.17.3 Guidance Notes'!$A$1
Name Guidance_notes_MHBS: #REF!
Name Guidance_notes_MHBS: 'T1.1 Guidance Notes'!$A$1
Name Guidance_notes_MHBS: 'T3.6 Guidance Notes'!$A$1
Name Guidance_notes_MHBS: 'T3.11.5 T3.6 Guidance Notes'!$A$1
Name Guidance_notes_Monocoque_Attachments: #REF!
Name Guidance_notes_Monocoque_Attachments: 'Monocoque Attachments Guidance'!$A$1
Name Guidance_notes_Perimeter_Shear: 'T4.5 Guidance Notes'!$A$1
Name Guidance_notes_Perimeter_Shear: 'T3.6.11 Guidance Notes'!$A$1
Name Guidance_notes_SIS: #REF!
Name Guidance_notes_SIS: 'T3.15 T3.6 Guidance Notes'!$A$1
Name Guidance_notes_TSPS: #REF!
Name Guidance_notes_TSPS: 'EV4.4 Guidance Notes'!$A$1
Name Innertable: MaterialData!$C$6:$V$11
Name Innertable: MaterialData!$C$6:$V$11
Name Innertable: MaterialData!$C$6:$V$11
Name Innertable: MaterialData!$C$6:$V$11
Name Innertable: MaterialData!$C$6:$V$11
Name Lijst: 'T1.2.1 T4.6 T4.8 Firewall'!$K$6:$L$7
Name Lijst: 'T1.2.1 T4.6 T4.8 Firewall'!$K$6:$L$7
Name Link_to_guidance_notes: #REF!
Name Link_to_guidance_notes: #REF!
Name Link_to_guidance_notes__Front_Hoop__FH__attachments: #REF!
Name Link_to_guidance_notes__Front_Hoop__FH__attachments: 'Front Hoop Attachment Guidance'!$A$1:$S$1
Name Link_to_guidance_notes_cell_stacks: #REF!
Name Link_to_guidance_notes_cell_stacks: #REF!
Name Link_to_guidance_notes_TSAC_attachment: 'EV5.5 TSAC Attachment Guidance'!$A$1
Name Material: MaterialData!$C$3:$V$3
Name Material: MaterialData!$C$3:$V$3
Name Material: MaterialData!$C$3:$V$3
Name Material: MaterialData!$C$3:$V$3
Name Material: MaterialData!$C$3:$V$3
Name Materialname: MaterialData!$C$4:$V$4
Name Materialname: MaterialData!$C$4:$V$4
Name Materials: MaterialData!$C$3:$V$3
Name Materials: MaterialData!$C$3:$V$3
Name Materials: MaterialData!$C$3:$V$3
Name Materials: MaterialData!$C$3:$V$3
Name Materials: MaterialData!$C$3:$V$3
Name Metallic_Mats: MaterialData!$C$3:$F$3
Name Metallic_Mats: MaterialData!$C$3:$F$3
Name Metallic_Mats: MaterialData!$C$3:$F$3
Name Metallic_Mats: MaterialData!$C$3:$F$3
Name Metallic_Mats: MaterialData!$C$3:$F$3
Name Table: MaterialData!$B$3:$V$11
Name Table: MaterialData!$B$3:$V$11
Name Tube_Type: MaterialData!$B$27:$B$28
Name Tube_Type: MaterialData!$B$27:$B$28

Sheet Read_Me
A1: 2026 | B1: V1.3 | C1: FS Structural Equivalency Spreadsheet Guide
A3: The SES template has been created to simplify the process of proving structural equivalency.
A5: Please enter your values in the yellow cells and paste all the images in the specific tabs which shows your entered values.
A7: All dimensions and units must follow the European SI System!
A9: The current SES includes formula's that only work with versions of Office 2021 and newer (e.g. Office 365)!
A11: The final decision about all designs will be made at technical inspection. Approval of an SES does not guarantee passing Tech. Inspection!
A13: As downloaded the spreadsheet assumes a baseline steel chassis design. The majority of the cells in the spreadsheet are locked, you can only edit the cells shaded yellow.
A14: Cells shaded grey are dependant on the data entered in yellow cells, the formulae in these grey cells have been left visible so you can see how the results are calculated.
A15: The vast majority of the tabs can be accessed using the hyperlinks on the cover sheet. If you enable macros when opening the document "Ctrl+e" will return you to the cover sheet.
A16: The SES has been extensively tested, but if you think you have found a mistake in the document or have any questions on how to use the template please submit a question in the usual manner.
A17: Please read the guidance notes located at the end of the workbook.
A19: If you find a new problem with the SES template or require a clarification 72 hours or less before the SES submission deadline please include your own
A20: proof of equivalency in the "Additional Info" tab as well as filing a Rules question.
B22: Teams are not permitted to rename the name of the TAB or to delete any TAB
A24: Revisions:
A25: V1.0 | B25: First release for 2026 rules
B26: - Updates to MaterialData/T3.5 (now T3.6) Laminate Test TABs, new TAB Laminate Table included, TABs T3.5 Laminate Tests, T3.5.9 Shear Tests reduced to singular TAB.
B27: - New TABs included/moved forward for Composite & Metal Datasheets
B28: - 'T3.3.3 (T3.2.2) Additional Info' TAB redundant and deleted due to new 'Metal Datasheets' TAB
B29: - T3.5.8 Shear Tests TAB: corrected incorrect peak force input into calculation for SIS & FBHS (lower peak must be used, instead of highest)
B30: - T3.4.2 Proof incorporated in new TAB Laminate Table
B31: - T3.15 T3.6 SIS TAB: check for sufficient energy absorption incorporated, failure if effective panel height smaller than 275mm AND linear scale of 65J requirement drops below 100%
B32: - In A2.2 First Year vehicle TAB: Additional comments cells removed, redundant due to large editable area below
B33: - References to Rules updated
A34: V1.1 | B34: - In ReadMe: message added regarding compatible versions (Office 2021 and younger)
B35: - Drop down selection edited for Composite Datasheets to include Bidirectional;Triaxial;Quadraxial instead of Woven Fabric;Non-Crimp Fabric, updated areal weight calculations to reflect those
B36: - T3.6 Laminate Tests TAB: renaming of materials and editability of support span for different steel tube test
B37: - Editable area definitions reinstated in several TAB's, amongst which: MaterialData, T3.9 Main Hoop, T3.10 Front Hoop and T3.11 Main Hoop Bracing, T4.5 Harness Attachments, T1.2.1 T4.6 T4.8 Firewall
B38: - T5.5 Shoulder Harness Bar: formatting fixed
B39: - Repaired drop-down and formatting in T1.2.1 T4.6 T4.8 Firewall TAB
B40: - University Name Reference in Metal, Composite Datasheets and Laminate Table TAB's corrected
B41: - Several TAB's: cell H/K27 corrected color formatting
B42: - T4.5 Harness Attachments TAB: Combined belts - corrected FAIL criteria (>365 Mpa) in cell AE18
B43: - Metal Datasheets TAB: formatting fixed when dropdown is selected to be aluminium (material 1-3), some formulae corrected to display N/A
B44: - T3.16 FH & FH Bing Attachments and T3.16 MH & MH Bing Attachments TAB's: fixed broken links to MaterialData TAB
B45: - Cover Sheet: fixed links to A/TSPS Side/Rear
A46: V1.2 | B46: - Editable area definition reinstated in TAB T3.6 Laminate Tests: from Laminate 10 onwards
B47: - In Laminate Table TAB: Corrected Column for T3.4.3 Compliance Check
A48: V1.3 | B48: - In T1.2.1 T4.6 T4.8 Firewall TAB: editable area reinstated
B49: - In Metal Datasheets TAB: Plastic Strain [%] link to elastic modulus corrected for other metals
...

Sheet Version History
A1: If you have to resubmit your SES then please update the table below, indicating what changes you have made from the previous submission.
A3: Submission Version | B3: Revision Comments
A4: V1.0 | B4: Changed Layup of the ACPS
B5: Added Pictures of the manufacturing process of the monococque and laminating the front hoop
B6: added blind inserts
B7: updated the harness att. tests to the present
A8: V1.1 | B8: Added the non SES Area of the FHB light pink area
B9: Added proof of a single piece monocoque
A10: V3.0 | B10: Added the calculation needed to ensure strength equivalence of the laminated front hoop

Sheet Rules Clarifications
A1: Details of any rules clarifications must be referenced and appended in this tab.
A3: Clarification ID | B3: Details of Clarification Question and Answer
A4: R-013862 | B4: question regarding T3.15.3: is it rule compliant if a nut and washer are within the 25mm range of the TSAC; compliant this season.

Sheet Cover Sheet
A1: =CONCATENATE(Read_Me!A1," FS STRUCTURAL EQUIVALENCY SPREADSHEET (SES) ",Read_Me!B1," - COVER SHEET") -> 2026 FS STRUCTURAL EQUIVALENCY SPREADSHEET (SES) V1.3 - COVER SHEET
A3: This form must be completed and submitted by all teams no later than the date specified in the Action Deadlines on specific event website. The Technical Committee will review all submissions which deviate from the FS rules and reply with a decision about the requested deviation. All requests will have a confirmation of receipt sent to the team. Structural Equivalency Spreadsheets (SES) must be submitted electronically in Microsoft Excel Format (*.xlsx). The submissions must be named as follows: schoolname_ses.xlsx using the complete school name. Please submit as described in the Action Deadlines for each event.
A11: In the event that the FS Technical Committee requests additional information or calculations, teams have seven days from the date of request to submit the requested information.
A14: University Name | D14: OTH Amberg-Weiden | K14: Car No.(s) & Event(s) | O14: FSA E32; FSG 23; FSP E23
A15: Team Contact | D15: Jan Frederking | K15: Email Address | N15: mechanics@runningsnail.oth-aw.de
A16: Faculty Advisor | D16: Prof. Dr. - Ing. Tobias Skubacz | K16: Email Address | N16: t.skubacz@oth-aw.de
A17: Powertrain Type | D17: Electric Vehicle | T17: Tube and Laminate Equivalency | AC17: Tube 1 | AG17: Tube 2 | AK17: Tube 3 | AO17: Composite
A18: Is proof of equivalency for your design required for any of the rules? | T18: EI / Safety Factor | U18: Area | V18: Yield | W18: UTS | X18: Yield as Welded | Y18: UTS as Welded | Z18: Max Bending Load at UTS | AA18: Max deflection at max baseline load | AB18: Energy absorbed during bending | AC18: Tube Material | AD18: Tube type | AE18: Outside Dimension | AF18: Wall thickness | AG18: Tube Material | AH18: Tube type | AI18: Outside Dimension | AJ18: Wall thickness | AK18: Tube Material | AL18: Tube type | AM18: Outside Dimension | AN18: Wall thickness | AO18: Material | AP18: Panel Thickness | AQ18: Inner Skin Thickness | AR18: Outer Skin Thickness | AS18: Panel Height | AT18: General status
A19: =IF(COUNTIF(A24:B47,"NO")>0,"Yes. Chassis deviates from baseline requirements","No. Chassis does not deviate from baseline requirements") -> Yes. Chassis deviates from baseline requirements
A21: Baseline Material Used | C21: Alternative Material Used | E21: Rule No. | G21: Rule Description | O21: Design Description and/or Material Name
A24: =IF(AND('T3.9 Main Hoop Tubing'!D13>='T3.9 Main Hoop Tubing'!C13,'T3.9 Main Hoop Tubing'!D14>='T3.9 Main Hoop Tubing'!C14),"YES","NO") -> NO | C24: NO | E24: T3.9 | G24: Main Roll Hoop Tubing | O24: 1.0576 (S355J2H) | T24: =IF(A24="no",'T3.9 Main Hoop Tubing'!E20,"NA") -> 149.49141 | U24: =IF(A24="no",'T3.9 Main Hoop Tubing'!E21,"NA") -> 101.44928 | V24: =IF(A24="no",'T3.9 Main Hoop Tubing'!E22,"NA") -> 101.44928 | W24: =IF(A24="no",'T3.9 Main Hoop Tubing'!E23,"NA") -> 101.44928 | X24: =IF(A24="no",'T3.9 Main Hoop Tubing'!E24,"NA") -> 101.44928 | Y24: =IF(A24="no",'T3.9 Main Hoop Tubing'!E25,"NA") -> 101.44928 | Z24: =IF(A24="no",'T3.9 Main Hoop Tubing'!E26,"NA") -> 126.5694 | AA24: =IF(A24="no",'T3.9 Main Hoop Tubing'!E27,"NA") -> 66.893474 | AB24: =IF(A24="no",'T3.9 Main Hoop Tubing'!E28,"NA") -> 107.16209 | AC24: ='T3.9 Main Hoop Tubing'!D4 -> Steel | AD24: ='T3.9 Main Hoop Tubing'!D5 -> Round | AE24: ='T3.9 Main Hoop Tubing'!D13 -> 30 | AF24: ='T3.9 Main Hoop Tubing'!D14 -> 2
A25: =IF(AND('T3.10 Front Hoop Tubing'!D4='T3.10 Front Hoop Tubing'!C4,'T3.10 Front Hoop Tubing'!D5='T3.10 Front Hoop Tubing'!C5,'T3.10 Front Hoop Tubing'!D13>='T3.10 Front Hoop Tubing'!C13,'T3.10 Front Hoop Tubing'!D14>='T3.10 Front Hoop Tubing'!C14),"YES","NO") -> NO | C25: =IF(A25="N/A","N/A",IF(A25="YES","NO","YES")) -> YES | E25: T3.10 | G25: Front Roll Hoop Tubing | T25: =IF(A25="no",'T3.10 Front Hoop Tubing'!E20,"NA") -> 162.43589 | U25: =IF(A25="no",'T3.10 Front Hoop Tubing'!E21,"NA") -> NA | V25: =IF(A25="no",'T3.10 Front Hoop Tubing'!E22,"NA") -> 141.8744 | W25: =IF(A25="no",'T3.10 Front Hoop Tubing'!E23,"NA") -> 148.19073 | X25: =IF(A25="no",'T3.10 Front Hoop Tubing'!E24,"NA") -> 122.09257 | Y25: =IF(A25="no",'T3.10 Front Hoop Tubing'!E25,"NA") -> 100.1516 | Z25: =IF(A25="no",'T3.10 Front Hoop Tubing'!E26,"NA") -> 297.70402 | AA25: =IF(A25="no",'T3.10 Front Hoop Tubing'!E27,"NA") -> 61.562749 | AB25: =IF(A25="no",'T3.10 Front Hoop Tubing'!E28,"NA") -> 545.61639 | AC25: ='T3.10 Front Hoop Tubing'!D4 -> Aluminium 2 | AD25: ='T3.10 Front Hoop Tubing'!D5 -> Square | AE25: ='T3.10 Front Hoop Tubing'!D13 -> 35.5 | AF25: ='T3.10 Front Hoop Tubing'!D14 -> 2
A26: =IF(AND('T3.11 Main Hoop Bracing'!D13>='T3.11 Main Hoop Bracing'!C13,'T3.11 Main Hoop Bracing'!D14>='T3.11 Main Hoop Bracing'!C14,'T3.11 Main Hoop Bracing'!D5='T3.11 Main Hoop Bracing'!C5),"YES","NO") -> YES | C26: =IF(A26="N/A","N/A",IF(A26="YES","NO","YES")) -> NO | E26: T3.11 | G26: Main Roll Hoop Bracing Tubing | O26: 1.0576 (S355J2H) | T26: =IF(A26="NO",'T3.11 Main Hoop Bracing'!E20,"NA") -> NA | U26: =IF(A26="NO",'T3.11 Main Hoop Bracing'!E21,"NA") -> NA | V26: =IF(A26="NO",'T3.11 Main Hoop Bracing'!E22,"NA") -> NA | W26: =IF(A26="NO",'T3.11 Main Hoop Bracing'!E23,"NA") -> NA | X26: =IF(A26="NO",'T3.11 Main Hoop Bracing'!E24,"NA") -> NA | Y26: =IF(A26="NO",'T3.11 Main Hoop Bracing'!E25,"NA") -> NA | Z26: =IF(A26="NO",'T3.11 Main Hoop Bracing'!E26,"NA") -> NA | AA26: =IF(A26="NO",'T3.11 Main Hoop Bracing'!E27,"NA") -> NA | AB26: =IF(A26="NO",'T3.11 Main Hoop Bracing'!E28,"NA") -> NA | AC26: ='T3.11 Main Hoop Bracing'!D4 -> Steel | AD26: ='T3.11 Main Hoop Bracing'!D5 -> Round | AE26: ='T3.11 Main Hoop Bracing'!D13 -> 25.4 | AF26: ='T3.11 Main Hoop Bracing'!D14 -> 1.7
A27: =IF(NOT('T3.11.5 T3.6 MHoop Brace Spt'!F2="tubing only"),"N/A",IF(AND('T3.11.5 T3.6 MHoop Brace Spt'!E5='T3.11.5 T3.6 MHoop Brace Spt'!C5,'T3.11.5 T3.6 MHoop Brace Spt'!E15>='T3.11.5 T3.6 MHoop Brace Spt'!C15,'T3.11.5 T3.6 MHoop Brace Spt'!E16>='T3.11.5 T3.6 MHoop Brace Spt'!C16),"YES","NO")) -> N/A | C27: =IF(A27="N/A","N/A",IF(A27="YES","NO","YES")) -> N/A | E27: T3.11.5 | G27: Main Hoop Bracing Support - Tube Frames | O27: / | T27: =IF(A27="NO",'T3.11.5 T3.6 MHoop Brace Spt'!$H$27,"NA") -> NA | U27: =IF(A27="NO",'T3.11.5 T3.6 MHoop Brace Spt'!$H$28,"NA") -> NA | V27: =IF(A27="NO",'T3.11.5 T3.6 MHoop Brace Spt'!$H$29,"NA") -> NA | W27: =IF(A27="NO",'T3.11.5 T3.6 MHoop Brace Spt'!$H$30,"NA") -> NA | X27: =IF(A27="NO",'T3.11.5 T3.6 MHoop Brace Spt'!$H$31,"NA") -> NA | Y27: =IF(A27="NO",'T3.11.5 T3.6 MHoop Brace Spt'!$H$32,"NA") -> NA | Z27: =IF(A27="NO",'T3.11.5 T3.6 MHoop Brace Spt'!$H$33,"NA") -> NA | AA27: =IF(A27="NO",'T3.11.5 T3.6 MHoop Brace Spt'!$H$34,"NA") -> NA | AB27: =IF(A27="NO",'T3.11.5 T3.6 MHoop Brace Spt'!$H$35,"NA") -> NA | AC27: =IF(A27="N/A","",IF('T3.11.5 T3.6 MHoop Brace Spt'!$F$2="composite only","",'T3.11.5 T3.6 MHoop Brace Spt'!E5)) | AD27: =IF(A27="N/A","",IF('T3.11.5 T3.6 MHoop Brace Spt'!$F$2="composite only","",'T3.11.5 T3.6 MHoop Brace Spt'!$E$6)) | AE27: =IF(A27="N/A","",IF('T3.11.5 T3.6 MHoop Brace Spt'!$F$2="composite only","",'T3.11.5 T3.6 MHoop Brace Spt'!$E$15)) | AF27: =IF(A27="N/A","",IF('T3.11.5 T3.6 MHoop Brace Spt'!$F$2="composite only","",'T3.11.5 T3.6 MHoop Brace Spt'!$E$16))
A28: =IF('T3.12 T3.6 FHoop Bracing'!F2="tubing only",IF(AND('T3.12 T3.6 FHoop Bracing'!E6='T3.12 T3.6 FHoop Bracing'!C6,'T3.12 T3.6 FHoop Bracing'!E15>='T3.12 T3.6 FHoop Bracing'!C15,'T3.12 T3.6 FHoop Bracing'!E16>='T3.12 T3.6 FHoop Bracing'!C16,'T3.12 T3.6 FHoop Bracing'!E5='T3.12 T3.6 FHoop Bracing'!C5),"YES","NO"),"N/A") -> N/A | C28: =IF(A28="N/A","N/A",IF(A28="YES","NO","YES")) -> N/A | E28: T3.12 | G28: Front Hoop Bracing - Tube Frames | O28: / | T28: =IF($A$28="NO",'T3.12 T3.6 FHoop Bracing'!$H$27,"NA") -> NA | U28: =IF($A$28="NO",'T3.12 T3.6 FHoop Bracing'!$H$28,"NA") -> NA | V28: =IF($A$28="NO",'T3.12 T3.6 FHoop Bracing'!$H$29,"NA") -> NA | W28: =IF($A$28="NO",'T3.12 T3.6 FHoop Bracing'!$H$30,"NA") -> NA | X28: =IF($A$28="NO",'T3.12 T3.6 FHoop Bracing'!$H$31,"NA") -> NA | Y28: =IF($A$28="NO",'T3.12 T3.6 FHoop Bracing'!$H$32,"NA") -> NA | Z28: =IF($A$28="NO",'T3.12 T3.6 FHoop Bracing'!$H$33,"NA") -> NA | AA28: =IF($A$28="NO",'T3.12 T3.6 FHoop Bracing'!$H$34,"NA") -> NA | AB28: =IF($A$28="NO",'T3.12 T3.6 FHoop Bracing'!$H$35,"NA") -> NA | AC28: =IF(A28="N/A","",IF('T3.12 T3.6 FHoop Bracing'!$F$2="Composite Only","",'T3.12 T3.6 FHoop Bracing'!$E$5)) | AD28: =IF(A28="N/A","",IF('T3.12 T3.6 FHoop Bracing'!$F$2="Composite Only","",'T3.12 T3.6 FHoop Bracing'!$E$6)) | AE28: =IF(A28="N/A","",IF('T3.12 T3.6 FHoop Bracing'!$F$2="Composite Only","",'T3.12 T3.6 FHoop Bracing'!$E$15)) | AF28: =IF(A28="N/A","",IF('T3.12 T3.6 FHoop Bracing'!$F$2="Composite Only","",'T3.12 T3.6 FHoop Bracing'!$E$16))
A29: =IF(NOT('T3.13 T3.6 Ft Bulkhead'!F2="tubing only"),"N/A",IF(AND('T3.13 T3.6 Ft Bulkhead'!E5='T3.13 T3.6 Ft Bulkhead'!C5,'T3.13 T3.6 Ft Bulkhead'!E17>='T3.13 T3.6 Ft Bulkhead'!C17,'T3.13 T3.6 Ft Bulkhead'!E18>='T3.13 T3.6 Ft Bulkhead'!C18),"YES","NO")) -> N/A | C29: =IF(A29="N/A","N/A",IF(A29="YES","NO","YES")) -> N/A | E29: T3.13 | G29: Front Bulkhead - Tube Frames | O29: / | T29: =IF($A$29="NO",'T3.13 T3.6 Ft Bulkhead'!$H30,"NA") -> NA | U29: =IF($A$29="NO",'T3.13 T3.6 Ft Bulkhead'!$H31,"NA") -> NA | V29: =IF($A$29="NO",'T3.13 T3.6 Ft Bulkhead'!$H32,"NA") -> NA | W29: =IF($A$29="NO",'T3.13 T3.6 Ft Bulkhead'!$H33,"NA") -> NA | X29: =IF($A$29="NO",'T3.13 T3.6 Ft Bulkhead'!$H34,"NA") -> NA | Y29: =IF($A$29="NO",'T3.13 T3.6 Ft Bulkhead'!$H35,"NA") -> NA | Z29: =IF($A$29="NO",'T3.13 T3.6 Ft Bulkhead'!$H36,"NA") -> NA | AA29: =IF($A$29="NO",'T3.13 T3.6 Ft Bulkhead'!$H37,"NA") -> NA | AB29: =IF($A$29="NO",'T3.13 T3.6 Ft Bulkhead'!$H38,"NA") -> NA | AC29: =IF(A29="N/A","",IF('T3.13 T3.6 Ft Bulkhead'!$F$2="Composite only","",'T3.13 T3.6 Ft Bulkhead'!$E$5)) | AD29: =IF(A29="N/A","",IF('T3.13 T3.6 Ft Bulkhead'!$F$2="Composite only","",'T3.13 T3.6 Ft Bulkhead'!$E$6)) | AE29: =IF(A29="N/A","",IF('T3.13 T3.6 Ft Bulkhead'!$F$2="Composite only","",'T3.13 T3.6 Ft Bulkhead'!$E$18)) | AF29: =IF(A29="N/A","",IF('T3.13 T3.6 Ft Bulkhead'!$F$2="Composite only","",'T3.13 T3.6 Ft Bulkhead'!$E$19))
A30: =IF(NOT('T3.14 T3.6 FBH Spt Structure'!F2="tubing only"),"N/A",IF('T3.14 T3.6 FBH Spt Structure'!G17="YES","YES","NO")) -> N/A | C30: =IF(A30="N/A","N/A",IF(A30="YES","NO","YES")) -> N/A | E30: T3.14 | G30: Front Bulkhead Support - Tube Frames | O30: / | T30: =IF($A$30="NO",'T3.14 T3.6 FBH Spt Structure'!$K$27,"NA") -> NA | U30: =IF($A$30="NO",'T3.14 T3.6 FBH Spt Structure'!$K$28,"NA") -> NA | V30: =IF($A$30="NO",'T3.14 T3.6 FBH Spt Structure'!$K$29,"NA") -> NA | W30: =IF($A$30="NO",'T3.14 T3.6 FBH Spt Structure'!$K$30,"NA") -> NA | X30: =IF($A$30="NO",'T3.14 T3.6 FBH Spt Structure'!$K$31,"NA") -> NA | Y30: =IF($A$30="NO",'T3.14 T3.6 FBH Spt Structure'!$K$32,"NA") -> NA | Z30: =IF($A$30="NO",'T3.14 T3.6 FBH Spt Structure'!$K$33,"NA") -> NA | AA30: =IF($A$30="NO",'T3.14 T3.6 FBH Spt Structure'!$K$34,"NA") -> NA | AB30: =IF($A$30="NO",'T3.14 T3.6 FBH Spt Structure'!$K$35,"NA") -> NA | AC30: =IF('T3.14 T3.6 FBH Spt Structure'!$F$2="tubing only",'T3.14 T3.6 FBH Spt Structure'!$E$5,"") | AD30: =IF('T3.14 T3.6 FBH Spt Structure'!$F$2="tubing only",'T3.14 T3.6 FBH Spt Structure'!$E$6,"") | AE30: =IF('T3.14 T3.6 FBH Spt Structure'!$F$2="tubing only",'T3.14 T3.6 FBH Spt Structure'!$E$15,"") | AF30: =IF('T3.14 T3.6 FBH Spt Structure'!$F$2="tubing only",'T3.14 T3.6 FBH Spt Structure'!$E$16,"") | AG30: =IF('T3.14 T3.6 FBH Spt Structure'!$F$2="tubing only",IF('T3.14 T3.6 FBH Spt Structure'!$F$14>0,'T3.14 T3.6 FBH Spt Structure'!$F$5,""),"") | AH30: =IF('T3.14 T3.6 FBH Spt Structure'!$F$2="tubing only",IF('T3.14 T3.6 FBH Spt Structure'!$F$14>0,'T3.14 T3.6 FBH Spt Structure'!$F$6,""),"") | AI30: =IF('T3.14 T3.6 FBH Spt Structure'!$F$2="tubing only",IF('T3.14 T3.6 FBH Spt Structure'!$F$14>0,'T3.14 T3.6 FBH Spt Structure'!$F$15,""),"") | AJ30: =IF('T3.14 T3.6 FBH Spt Structure'!$F$2="tubing only",IF('T3.14 T3.6 FBH Spt Structure'!$F$14>0,'T3.14 T3.6 FBH Spt Structure'!$F$16,""),"") | AK30: =IF('T3.14 T3.6 FBH Spt Structure'!$F$2="tubing only",IF('T3.14 T3.6 FBH Spt Structure'!$G$14>0,'T3.14 T3.6 FBH Spt Structure'!$G$5,""),"") | AL30: =IF('T3.14 T3.6 FBH Spt Structure'!$F$2="tubing only",IF('T3.14 T3.6 FBH Spt Structure'!$G$14>0,'T3.14 T3.6 FBH Spt Structure'!$G$6,""),"") | AM30: =IF('T3.14 T3.6 FBH Spt Structure'!$F$2="tubing only",IF('T3.14 T3.6 FBH Spt Structure'!$G$14>0,'T3.14 T3.6 FBH Spt Structure'!$G$15,""),"") | AN30: =IF('T3.14 T3.6 FBH Spt Structure'!$F$2="tubing only",IF('T3.14 T3.6 FBH Spt Structure'!$G$14>0,'T3.14 T3.6 FBH Spt Structure'!$G$16,""),"")
A31: =IF(NOT('T3.15 T3.6 SIS'!F2="tubing only"),"N/A",IF('T3.15 T3.6 SIS'!G17="YES","YES","NO")) -> N/A | C31: =IF(A31="N/A","N/A",IF(A31="YES","NO","YES")) -> N/A | E31: T3.15 | G31: Side Impact Structure - Tube Frames | O31: / | T31: =IF($A$31="NO",'T3.15 T3.6 SIS'!$L$27,"NA") -> NA | U31: =IF($A$31="NO",'T3.15 T3.6 SIS'!$L$28,"NA") -> NA | V31: =IF($A$31="NO",'T3.15 T3.6 SIS'!$L$29,"NA") -> NA | W31: =IF($A$31="NO",'T3.15 T3.6 SIS'!$L$30,"NA") -> NA | X31: =IF($A$31="NO",'T3.15 T3.6 SIS'!$L$31,"NA") -> NA | Y31: =IF($A$31="NO",'T3.15 T3.6 SIS'!$L$32,"NA") -> NA | Z31: =IF($A$31="NO",'T3.15 T3.6 SIS'!$L$33,"NA") -> NA | AA31: =IF($A$31="NO",'T3.15 T3.6 SIS'!$L$34,"NA") -> NA | AB31: =IF($A$31="NO",'T3.15 T3.6 SIS'!$L$35,"NA") -> NA | AC31: =IF('T3.15 T3.6 SIS'!$F$2="tubing only",'T3.15 T3.6 SIS'!$E$5,"") | AD31: =IF('T3.15 T3.6 SIS'!$F$2="tubing only",'T3.15 T3.6 SIS'!$E$6,"") | AE31: =IF('T3.15 T3.6 SIS'!$F$2="tubing only",'T3.15 T3.6 SIS'!$E$15,"") | AF31: =IF('T3.15 T3.6 SIS'!$F$2="tubing only",'T3.15 T3.6 SIS'!$E$16,"") | AG31: =IF('T3.15 T3.6 SIS'!$F$2="tubing only",IF('T3.15 T3.6 SIS'!$F$14>0,'T3.15 T3.6 SIS'!$F$5,""),"") | AH31: =IF('T3.15 T3.6 SIS'!$F$2="tubing only",IF('T3.15 T3.6 SIS'!$F$14>0,'T3.15 T3.6 SIS'!$F$6,""),"") | AI31: =IF('T3.15 T3.6 SIS'!$F$2="tubing only",IF('T3.15 T3.6 SIS'!$F$14>0,'T3.15 T3.6 SIS'!$F$15,""),"") | AJ31: =IF('T3.15 T3.6 SIS'!$F$2="tubing only",IF('T3.15 T3.6 SIS'!$F$14>0,'T3.15 T3.6 SIS'!$F$16,""),"") | AK31: =IF('T3.15 T3.6 SIS'!$F$2="tubing only",IF('T3.15 T3.6 SIS'!$G$14>0,'T3.15 T3.6 SIS'!$G$5,""),"") | AL31: =IF('T3.15 T3.6 SIS'!$F$2="tubing only",IF('T3.15 T3.6 SIS'!$G$14>0,'T3.15 T3.6 SIS'!$G$6,""),"") | AM31: =IF('T3.15 T3.6 SIS'!$F$2="tubing only",IF('T3.15 T3.6 SIS'!$G$14>0,'T3.15 T3.6 SIS'!$G$15,""),"") | AN31: =IF('T3.15 T3.6 SIS'!$F$2="tubing only",IF('T3.15 T3.6 SIS'!$G$14>0,'T3.15 T3.6 SIS'!$G$16,""),"")
A32: =IF(AND('T5.5 Shoulder Harness Bar'!F2="tubing only",'T5.5 Shoulder Harness Bar'!E5='T5.5 Shoulder Harness Bar'!C5,'T5.5 Shoulder Harness Bar'!E15>='T5.5 Shoulder Harness Bar'!C15,'T5.5 Shoulder Harness Bar'!E16>='T5.5 Shoulder Harness Bar'!C16),"YES","NO") -> NO | C32: =IF(A32="N/A","N/A",IF(A32="YES","NO","YES")) -> YES | E32: T5.5 | G32: Shoulder Harness Bar | O32: Deltatech GG200T(M40J)-DT120-42 (fabric); Deltatech M40J-200-DT120-36; CP006; PAMG-XR1 5056 Aluminium Honeycomb 1/8"; Deltatech ZZ300T-DT120-44 45f/-20M/0M/20M/0M/45z/cp/18core/cp/45z/0M/20M/0M/-20M/45f | T32: =IF(A32="YES","NA",'T5.5 Shoulder Harness Bar'!H29) -> 147.78042 | U32: =IF(A32="YES","NA",'T5.5 Shoulder Harness Bar'!H30) -> 210.89183 | V32: =IF(A32="YES","NA",'T5.5 Shoulder Harness Bar'!H31) -> 244.52927 | W32: =IF(A32="YES","NA",'T5.5 Shoulder Harness Bar'!H32) -> 204.33267 | X32: =IF(A32="YES","NA",'T5.5 Shoulder Harness Bar'!H33) -> 414.34126 | Y32: =IF(A32="YES","NA",'T5.5 Shoulder Harness Bar'!H34) -> 248.60475 | Z32: =IF(A32="YES","NA",'T5.5 Shoulder Harness Bar'!H35) -> 350.64233 | AA32: =IF(A32="YES","NA",'T5.5 Shoulder Harness Bar'!H36) -> 67.667961 | AB32: =IF(A32="YES","NA",'T5.5 Shoulder Harness Bar'!H37) -> 831.97787 | AC32: =IF('T5.5 Shoulder Harness Bar'!F2="composite only","",'T5.5 Shoulder Harness Bar'!E5) | AD32: =IF('T5.5 Shoulder Harness Bar'!F2="composite only","",'T5.5 Shoulder Harness Bar'!E6) | AE32: =IF('T5.5 Shoulder Harness Bar'!F2="composite only","",'T5.5 Shoulder Harness Bar'!E15) | AF32: =IF('T5.5 Shoulder Harness Bar'!F2="composite only","",'T5.5 Shoulder Harness Bar'!E16) | AO32: =IF('T5.5 Shoulder Harness Bar'!F2="tubing only","",'T5.5 Shoulder Harness Bar'!F5) -> Other 5 | AP32: =IF('T5.5 Shoulder Harness Bar'!F2="tubing only","",'T5.5 Shoulder Harness Bar'!F20) -> 20 | AQ32: =IF('T5.5 Shoulder Harness Bar'!$F$2="tubing only","",'T5.5 Shoulder Harness Bar'!F22) -> 1 | AR32: =IF('T5.5 Shoulder Harness Bar'!$F$2="tubing only","",'T5.5 Shoulder Harness Bar'!F23) -> 1 | AS32: =IF('T5.5 Shoulder Harness Bar'!F2="tubing only","",'T5.5 Shoulder Harness Bar'!F24) -> 182.86
A33: =IF('T3.17.3 IA AI Plate'!D23="YES","YES","NO") -> NO | C33: =IF(A33="N/A","N/A",IF(A33="YES","NO","YES")) -> YES | E33: T3.17.3 | G33: Impact Attenuator Anti-Intrusion Plate | O33: EN AW 5083 | T33: =IF(A33="YES","NA",IF('T3.17.3 IA AI Plate'!$D$23="NO","CH")) -> CH
A34: =IF('T3.12 T3.6 FHoop Bracing'!F2="tubing only","N/A","NO") -> NO | C34: =IF(A34="N/A","N/A",IF(A34="YES","NO","YES")) -> YES | E34: T3.12/T3.6 | G34: Front Hoop Bracing - Monocoques | O34: Deltatech GG200T(M40J)-DT120-42 (fabric); Deltatech M40J-200-DT120-36; CP006; PAMG-XR1 5056 Aluminium Honeycomb 1/8"; 45f/0M/-20M/0M/20M/0M/45f/0f/CP/18core/CP/0f/45f/0M/20M/0M/-20M/0M/45f | T34: =IF($A$34="NO",'T3.12 T3.6 FHoop Bracing'!$H$27,"NA") -> 66.406192 | U34: =IF($A$34="NO",'T3.12 T3.6 FHoop Bracing'!$H$28,"NA") -> NA | V34: =IF($A$34="NO",'T3.12 T3.6 FHoop Bracing'!$H$29,"NA") -> 119.76707 | W34: =IF($A$34="NO",'T3.12 T3.6 FHoop Bracing'!$H$30,"NA") -> 100.07934 | X34: =IF($A$34="NO",'T3.12 T3.6 FHoop Bracing'!$H$31,"NA") -> 202.93865 | Y34: =IF($A$34="NO",'T3.12 T3.6 FHoop Bracing'!$H$32,"NA") -> 121.76319 | Z34: =IF($A$34="NO",'T3.12 T3.6 FHoop Bracing'!$H$33,"NA") -> 161.93209 | AA34: =IF($A$34="NO",'T3.12 T3.6 FHoop Bracing'!$H$34,"NA") -> 150.58837 | AB34: =IF($A$34="NO",'T3.12 T3.6 FHoop Bracing'!$H$35,"NA") -> 394.87285 | AC34: =IF('T3.12 T3.6 FHoop Bracing'!$F$2="tubing Only","",'T3.12 T3.6 FHoop Bracing'!$E$5) -> Steel | AD34: =IF('T3.12 T3.6 FHoop Bracing'!$F$2="tubing Only","",'T3.12 T3.6 FHoop Bracing'!$E$6) -> Round | AE34: =IF('T3.12 T3.6 FHoop Bracing'!$F$2="tubing Only","",'T3.12 T3.6 FHoop Bracing'!$E$15) -> 25.4 | AF34: =IF('T3.12 T3.6 FHoop Bracing'!$F$2="tubing Only","",'T3.12 T3.6 FHoop Bracing'!$E$16) -> 1.6 | AO34: =IF('T3.12 T3.6 FHoop Bracing'!$F$2="tubing Only","",'T3.12 T3.6 FHoop Bracing'!$F$5) -> Other 6 | AP34: =IF('T3.12 T3.6 FHoop Bracing'!$F$2="tubing Only","",'T3.12 T3.6 FHoop Bracing'!$F$18) -> 20.8 | AQ34: =IF('T3.12 T3.6 FHoop Bracing'!$F$2="tubing Only","",'T3.12 T3.6 FHoop Bracing'!$F$20) -> 1.4 | AR34: =IF('T3.12 T3.6 FHoop Bracing'!$F$2="tubing Only","",'T3.12 T3.6 FHoop Bracing'!$F$20) -> 1.4 | AS34: =IF('T3.12 T3.6 FHoop Bracing'!$F$2="tubing Only","",'T3.12 T3.6 FHoop Bracing'!$F$22) -> 41.29
A35: =IF('T3.13 T3.6 Ft Bulkhead'!F2="tubing only","N/A","NO") -> NO | C35: =IF(A35="N/A","N/A",IF(A35="YES","NO","YES")) -> YES | E35: T3.13/T3.6 | G35: Front Bulkhead - Monocoques | O35: Deltatech T800S-150-DT120-34 EF; Aramid; CP006; PAMG-XR1 5056 Aluminium Honeycomb 1/8"; 0T/45a/0a/45a/0a/45a/0a/45a/0a/45a/CP/18core/CP/45a/0a/45a/0a/45a/0a/45a/0a/45a/0T | T35: =IF($A$35="NO",'T3.13 T3.6 Ft Bulkhead'!$H30,"NA") -> 221.14986 | U35: =IF($A$35="NO",'T3.13 T3.6 Ft Bulkhead'!$H31,"NA") -> NA | V35: =IF($A$35="NO",'T3.13 T3.6 Ft Bulkhead'!$H32,"NA") -> 135.54448 | W35: =IF($A$35="NO",'T3.13 T3.6 Ft Bulkhead'!$H33,"NA") -> 113.2632 | X35: =IF($A$35="NO",'T3.13 T3.6 Ft Bulkhead'!$H34,"NA") -> 229.6726 | Y35: =IF($A$35="NO",'T3.13 T3.6 Ft Bulkhead'!$H35,"NA") -> 137.80356 | Z35: =IF($A$35="NO",'T3.13 T3.6 Ft Bulkhead'!$H36,"NA") -> 428.73535 | AA35: =IF($A$35="NO",'T3.13 T3.6 Ft Bulkhead'!$H37,"NA") -> 45.218207 | AB35: =IF($A$35="NO",'T3.13 T3.6 Ft Bulkhead'!$H38,"NA") -> 831.17395 | AC35: =IF('T3.13 T3.6 Ft Bulkhead'!$F$2="tubes + Composite",'T3.13 T3.6 Ft Bulkhead'!$E$5,"") | AD35: =IF('T3.13 T3.6 Ft Bulkhead'!$F$2="tubes + composite",'T3.13 T3.6 Ft Bulkhead'!$E$6,"") | AE35: =IF('T3.13 T3.6 Ft Bulkhead'!$F$2="tubes + composite",'T3.13 T3.6 Ft Bulkhead'!$E$18,"") | AF35: =IF('T3.13 T3.6 Ft Bulkhead'!$F$2="tubes + composite",'T3.13 T3.6 Ft Bulkhead'!$E$19,"") | AO35: =IF('T3.13 T3.6 Ft Bulkhead'!$F$2="tubing only","",'T3.13 T3.6 Ft Bulkhead'!$F$5) -> Other 2 | AP35: =IF('T3.13 T3.6 Ft Bulkhead'!$F$2="tubing only","",'T3.13 T3.6 Ft Bulkhead'!$F$21) -> 23.5 | AQ35: =IF('T3.13 T3.6 Ft Bulkhead'!$F$2="tubing only","",'T3.13 T3.6 Ft Bulkhead'!$F$23) -> 2.75 | AR35: =IF('T3.13 T3.6 Ft Bulkhead'!$F$2="tubing only","",'T3.13 T3.6 Ft Bulkhead'!$F$24) -> 2.75 | AS35: =IF('T3.13 T3.6 Ft Bulkhead'!$F$2="tubing only","",'T3.13 T3.6 Ft Bulkhead'!$F$25) -> 96.42
A36: =IF('T3.14 T3.6 FBH Spt Structure'!F2="tubing only","N/A","NO") -> NO | C36: =IF(A36="N/A","N/A",IF(A36="YES","NO","YES")) -> YES | E36: T3.14/T3.6 | G36: Front Bulkhead Support - Monocoques | O36: Deltatech GG200T(M40J)-DT120-42 (fabric); Deltatech M40J-200-DT120-36; CP006; PAMG-XR1 5056 Aluminium Honeycomb 1/8";45f/-20M/0M/20M/0M/45f/0f/CP/18core/CP/0f/45f/0M/20M/0M/-20M/45f | T36: =IF($A$36="NO",'T3.14 T3.6 FBH Spt Structure'!$K$27,"NA") -> 165.74787 | U36: =IF($A$36="NO",'T3.14 T3.6 FBH Spt Structure'!$K$28,"NA") -> NA | V36: =IF($A$36="NO",'T3.14 T3.6 FBH Spt Structure'!$K$29,"NA") -> 344.70005 | W36: =IF($A$36="NO",'T3.14 T3.6 FBH Spt Structure'!$K$30,"NA") -> 288.03703 | X36: =IF($A$36="NO",'T3.14 T3.6 FBH Spt Structure'!$K$31,"NA") -> 584.07509 | Y36: =IF($A$36="NO",'T3.14 T3.6 FBH Spt Structure'!$K$32,"NA") -> 350.44505 | Z36: =IF($A$36="NO",'T3.14 T3.6 FBH Spt Structure'!$K$33,"NA") -> 451.70179 | AA36: =IF($A$36="NO",'T3.14 T3.6 FBH Spt Structure'!$K$34,"NA") -> 60.3326 | AB36: =IF($A$36="NO",'T3.14 T3.6 FBH Spt Structure'!$K$35,"NA") -> 1230.9932 | AC36: =IF('T3.14 T3.6 FBH Spt Structure'!$F$2="Tubes + composite",'T3.14 T3.6 FBH Spt Structure'!$E$5,"") | AD36: =IF('T3.14 T3.6 FBH Spt Structure'!$F$2="Tubes + composite",'T3.14 T3.6 FBH Spt Structure'!$E$6,"") | AE36: =IF('T3.14 T3.6 FBH Spt Structure'!$F$2="Tubes + composite",'T3.14 T3.6 FBH Spt Structure'!$E$15,"") | AF36: =IF('T3.14 T3.6 FBH Spt Structure'!$F$2="Tubes + composite",'T3.14 T3.6 FBH Spt Structure'!$E$16,"") | AG36: =IF('T3.14 T3.6 FBH Spt Structure'!$F$2="Tubes + composite",IF('T3.14 T3.6 FBH Spt Structure'!$F$14>0,'T3.14 T3.6 FBH Spt Structure'!$F$5,""),"") | AH36: =IF('T3.14 T3.6 FBH Spt Structure'!$F$2="Tubes + composite",IF('T3.14 T3.6 FBH Spt Structure'!$F$14>0,'T3.14 T3.6 FBH Spt Structure'!$F$6,""),"") | AI36: =IF('T3.14 T3.6 FBH Spt Structure'!$F$2="Tubes + composite",IF('T3.14 T3.6 FBH Spt Structure'!$F$14>0,'T3.14 T3.6 FBH Spt Structure'!$F$15,""),"") | AJ36: =IF('T3.14 T3.6 FBH Spt Structure'!$F$2="Tubes + composite",IF('T3.14 T3.6 FBH Spt Structure'!$F$14>0,'T3.14 T3.6 FBH Spt Structure'!$F$16,""),"") | AK36: =IF('T3.14 T3.6 FBH Spt Structure'!$F$2="Tubes + composite",IF('T3.14 T3.6 FBH Spt Structure'!$G$14>0,'T3.14 T3.6 FBH Spt Structure'!$G$5,""),"") | AL36: =IF('T3.14 T3.6 FBH Spt Structure'!$F$2="Tubes + composite",IF('T3.14 T3.6 FBH Spt Structure'!$G$14>0,'T3.14 T3.6 FBH Spt Structure'!$G$6,""),"") | AM36: =IF('T3.14 T3.6 FBH Spt Structure'!$F$2="Tubes + composite",IF('T3.14 T3.6 FBH Spt Structure'!$G$14>0,'T3.14 T3.6 FBH Spt Structure'!$G$15,""),"") | AN36: =IF('T3.14 T3.6 FBH Spt Structure'!$F$2="Tubes + composite",IF('T3.14 T3.6 FBH Spt Structure'!$G$14>0,'T3.14 T3.6 FBH Spt Structure'!$G$16,""),"") | AO36: =IF('T3.14 T3.6 FBH Spt Structure'!$F$2="tubing only","",'T3.14 T3.6 FBH Spt Structure'!$I$5) -> Other 1 | AP36: =IF('T3.14 T3.6 FBH Spt Structure'!$F$2="tubing only","",'T3.14 T3.6 FBH Spt Structure'!$I$18) -> 20.8 | AQ36: =IF('T3.14 T3.6 FBH Spt Structure'!$F$2="tubing only","",'T3.14 T3.6 FBH Spt Structure'!$I$20) -> 1.4 | AR36: =IF('T3.14 T3.6 FBH Spt Structure'!$F$2="tubing only","",'T3.14 T3.6 FBH Spt Structure'!$I$21) -> 1.4 | AS36: =IF('T3.14 T3.6 FBH Spt Structure'!$F$2="tubing only","",'T3.14 T3.6 FBH Spt Structure'!$I$22) -> 279.4
A37: =IF('T3.15 T3.6 SIS'!F2="tubing only","N/A","NO") -> NO | C37: =IF(A37="N/A","N/A",IF(A37="YES","NO","YES")) -> YES | E37: T3.15/T3.6 | G37: Side Impact Structure - Monocoques, Side | O37: Deltatech GG285P(T700)-DT120-40 (fabric); Deltatech M40J-200-DT120-36; CP006; PAMG-XR1 5056 Aluminium Honeycomb 1/8"; 45f/-20M/0M/20M/0M/45f/0f/CP/18core/CP/0f/45f/0M/20M/0M/-20M/45f | T37: =IF($A$37="NO",'T3.15 T3.6 SIS'!$L$27,"NA") -> 103.50175 | U37: =IF($A$37="NO",'T3.15 T3.6 SIS'!$L$28,"NA") -> NA | V37: =IF($A$37="NO",'T3.15 T3.6 SIS'!$L$29,"NA") -> NA | W37: =IF($A$37="NO",'T3.15 T3.6 SIS'!$L$30,"NA") -> NA | X37: =IF($A$37="NO",'T3.15 T3.6 SIS'!$L$31,"NA") -> NA | Y37: =IF($A$37="NO",'T3.15 T3.6 SIS'!$L$32,"NA") -> NA | Z37: =IF($A$37="NO",'T3.15 T3.6 SIS'!$L$33,"NA") -> NA | AA37: =IF($A$37="NO",'T3.15 T3.6 SIS'!$L$34,"NA") -> NA | AB37: =IF($A$37="NO",'T3.15 T3.6 SIS'!$L$35,"NA") -> 100.00402 | AC37: =IF('T3.15 T3.6 SIS'!$F$2="tubes + composite",'T3.15 T3.6 SIS'!$E$5,"") | AD37: =IF('T3.15 T3.6 SIS'!$F$2="tubes + composite",'T3.15 T3.6 SIS'!$E$6,"") | AE37: =IF('T3.15 T3.6 SIS'!$F$2="tubes + composite",'T3.15 T3.6 SIS'!$E$15,"") | AF37: =IF('T3.15 T3.6 SIS'!$F$2="tubes + composite",'T3.15 T3.6 SIS'!$E$16,"") | AG37: =IF('T3.15 T3.6 SIS'!$F$2="tubes + composite",IF('T3.15 T3.6 SIS'!$F$14>0,'T3.15 T3.6 SIS'!$F$5,""),"") | AH37: =IF('T3.15 T3.6 SIS'!$F$2="tubes + composite",IF('T3.15 T3.6 SIS'!$F$14>0,'T3.15 T3.6 SIS'!$F$6,""),"") | AI37: =IF('T3.15 T3.6 SIS'!$F$2="tubes + composite",IF('T3.15 T3.6 SIS'!$F$14>0,'T3.15 T3.6 SIS'!$F$15,""),"") | AJ37: =IF('T3.15 T3.6 SIS'!$F$2="tubes + composite",IF('T3.15 T3.6 SIS'!$F$14>0,'T3.15 T3.6 SIS'!$F$16,""),"") | AK37: =IF('T3.15 T3.6 SIS'!$F$2="tubes + composite",IF('T3.15 T3.6 SIS'!$G$14>0,'T3.15 T3.6 SIS'!$G$5,""),"") | AL37: =IF('T3.15 T3.6 SIS'!$F$2="tubes + composite",IF('T3.15 T3.6 SIS'!$G$14>0,'T3.15 T3.6 SIS'!$G$6,""),"") | AM37: =IF('T3.15 T3.6 SIS'!$F$2="tubes + composite",IF('T3.15 T3.6 SIS'!$G$14>0,'T3.15 T3.6 SIS'!$G$15,""),"") | AN37: =IF('T3.15 T3.6 SIS'!$F$2="tubes + composite",IF('T3.15 T3.6 SIS'!$G$14>0,'T3.15 T3.6 SIS'!$G$16,""),"") | AO37: =IF('T3.15 T3.6 SIS'!$F$2="Tubing only","",'T3.15 T3.6 SIS'!$I$5) -> Composite 1 | AP37: =IF('T3.15 T3.6 SIS'!$F$2="Tubing only","",'T3.15 T3.6 SIS'!$I$18) -> 20.8 | AQ37: =IF('T3.15 T3.6 SIS'!$F$2="Tubing only","",'T3.15 T3.6 SIS'!$I$20) -> 1.4 | AR37: =IF('T3.15 T3.6 SIS'!$F$2="Tubing only","",'T3.15 T3.6 SIS'!$I$21) -> 1.4 | AS37: =IF('T3.15 T3.6 SIS'!$F$2="Tubing only","",'T3.15 T3.6 SIS'!$I$22) -> 193.32
A38: =IF('T3.15 T3.6 SIS'!F2="tubing only","N/A","NO") -> NO | C38: =IF(A38="N/A","N/A",IF(A38="YES","NO","YES")) -> YES | E38: T3.15/T3.6 | G38: Side Impact Structure - Monocoques, Floor | O38: Deltatech GG200T(M40J)-DT120-42 (fabric); Deltatech M40J-200-DT120-36; CP006; PAMG-XR1 5056 Aluminium Honeycomb 1/8"; 45f/0M/0M/0M/0M/45f/CP/10core/CP/45f/21M/0M/-21M/0M/45f | AO38: =IF('T3.15 T3.6 SIS'!$F$2="Tubing only","",'T3.15 T3.6 SIS'!$J$5) -> Other 3 | AP38: =IF('T3.15 T3.6 SIS'!$F$2="Tubing only","",'T3.15 T3.6 SIS'!$J$18) -> 12.3 | AQ38: =IF('T3.15 T3.6 SIS'!$F$2="Tubing only","",'T3.15 T3.6 SIS'!$J$20) -> 1.15 | AR38: =IF('T3.15 T3.6 SIS'!$F$2="Tubing only","",'T3.15 T3.6 SIS'!$J$21) -> 1.15 | AS38: =IF('T3.15 T3.6 SIS'!$F$2="Tubing only","",'T3.15 T3.6 SIS'!$J$22) -> 202
A39: =IF('T3.11.5 T3.6 MHoop Brace Spt'!F2="tubing only","N/A","NO") -> NO | C39: =IF(A39="N/A","N/A",IF(A39="YES","NO","YES")) -> YES | E39: T3.11.5/T3.6 | G39: Main Hoop Bracing Support - Monocoques | O39: See SHB layup | T39: =IF(A39="NO",'T3.11.5 T3.6 MHoop Brace Spt'!$H$27,"NA") -> 131.87544 | U39: =IF(A39="NO",'T3.11.5 T3.6 MHoop Brace Spt'!$H$28,"NA") -> NA | V39: =IF(A39="NO",'T3.11.5 T3.6 MHoop Brace Spt'!$H$29,"NA") -> 273.37583 | W39: =IF(A39="NO",'T3.11.5 T3.6 MHoop Brace Spt'!$H$30,"NA") -> 228.43734 | X39: =IF(A39="NO",'T3.11.5 T3.6 MHoop Brace Spt'!$H$31,"NA") -> 463.22016 | Y39: =IF(A39="NO",'T3.11.5 T3.6 MHoop Brace Spt'!$H$32,"NA") -> 277.93209 | Z39: =IF(A39="NO",'T3.11.5 T3.6 MHoop Brace Spt'!$H$33,"NA") -> 357.07154 | AA39: =IF(A39="NO",'T3.11.5 T3.6 MHoop Brace Spt'!$H$34,"NA") -> 75.829133 | AB39: =IF(A39="NO",'T3.11.5 T3.6 MHoop Brace Spt'!$H$35,"NA") -> 966.82211 | AC39: =IF(A39="N/A","",IF('T3.11.5 T3.6 MHoop Brace Spt'!$F$2="tubes + composite",'T3.11.5 T3.6 MHoop Brace Spt'!E5,"")) | AD39: =IF(A39="N/A","",IF('T3.11.5 T3.6 MHoop Brace Spt'!$F$2="tubes + composite",'T3.11.5 T3.6 MHoop Brace Spt'!$E$6,"")) | AE39: =IF(A39="N/A","",IF('T3.11.5 T3.6 MHoop Brace Spt'!$F$2="tubes + composite",'T3.11.5 T3.6 MHoop Brace Spt'!$E$15,"")) | AF39: =IF(A39="N/A","",IF('T3.11.5 T3.6 MHoop Brace Spt'!$F$2="tubes + composite",'T3.11.5 T3.6 MHoop Brace Spt'!$E$16,"")) | AO39: =IF('T3.11.5 T3.6 MHoop Brace Spt'!F2="tubing only","",'T3.11.5 T3.6 MHoop Brace Spt'!F5) -> Other 4 | AP39: =IF('T3.11.5 T3.6 MHoop Brace Spt'!F2="tubing only","",'T3.11.5 T3.6 MHoop Brace Spt'!F18) -> 20 | AQ39: =IF('T3.11.5 T3.6 MHoop Brace Spt'!$F$2="tubing only","",'T3.11.5 T3.6 MHoop Brace Spt'!$F$20) -> 1 | AR39: =IF('T3.11.5 T3.6 MHoop Brace Spt'!$F$2="tubing only","",'T3.11.5 T3.6 MHoop Brace Spt'!$F$21) -> 1 | AS39: =IF('T3.11.5 T3.6 MHoop Brace Spt'!F2="tubing only","",'T3.11.5 T3.6 MHoop Brace Spt'!F22) -> 158.1
A40: =IF(A37="no","NO","N/A") -> NO | C40: =IF(A40="N/A","N/A",IF(A40="YES","NO","YES")) -> YES | E40: T3.16 | G40: Main Hoop & MH Bracing Attachments | O40: See SIS layup | T40: =IF(A40="N/A","NA",IF(OR('T3.16 MH & MH Bing Attachments'!C8="FAIL",'T3.16 MH & MH Bing Attachments'!E8="FAIL",'T3.16 MH & MH Bing Attachments'!I8="FAIL",'T3.16 MH & MH Bing Attachments'!K8="FAIL"),"FA","PA")) -> PA
A41: =IF(A36="no","NO","N/A") -> NO | C41: =IF(A41="N/A","N/A",IF(A41="YES","NO","YES")) -> YES | E41: T3.16 | G41: Front Hoop & FH Bracing Attachments | O41: See FBHS/ FHB layup | T41: =IF('T3.16 FH & FH Bing Attachments'!C3=0,"CH",IF(A41="N/A","NA",IF(OR('T3.16 FH & FH Bing Attachments'!C8="FAIL",'T3.16 FH & FH Bing Attachments'!E8="FAIL",'T3.16 FH & FH Bing Attachments'!I8="FAIL",'T3.16 FH & FH Bing Attachments'!K8="FAIL"),"FA","PA"))) -> CH
A42: =IF(OR('T4.5 Harness Attachments'!Q34="YES",'T4.5 Harness Attachments'!Q35="YES",'T4.5 Harness Attachments'!Q36="YES",'T4.5 Harness Attachments'!Q37="YES"),"NO","N/A") -> NO | C42: =IF(A42="N/A","N/A",IF(A42="YES","NO","YES")) -> YES | E42: T4.5 | G42: Safety Harness Attachment | O42: See MHBS for Shoulder Harness; See SIS Floor for Anti Submarine; 45f/-20M/0M/20M/0M/45z/cp/18core/cp/45z/0M/20M/0M/-20M/45f; 45f/0M/0M/0M/0M/45f/CP/10core/CP/45f/21M/0M/-21M/0M/45f | T42: =IF(A42="N/A","NA",IF('T4.5 Harness Attachments'!A35="PASS","PA","FA")) -> PA
A43: N/A | C43: N/A | E43: T3.16.6/T3.17.5 | G43: Attachment Plates/Panels - Monocoques | O43: See AIP and ACP | T43: =IF(A43="N/A","NA",IF('T3.16.6&3.17.5 Prim.Struc.Att.'!C24="FAIL","FA","PA")) -> NA
A44: N/A | C44: N/A | E44: T3.16.7 | G44: Blind Insert Attachments | T44: {=_xlfn.IFS(AND('T3.16.7 Prim.Struct.Att. Blind'!G38="N/A",'T3.16.7 Prim.Struct.Att. Blind'!AA38="N/A"),"NA",AND('T3.16.7 Prim.Struct.Att. Blind'!G38="PASS",'T3.16.7 Prim.Struct.Att. Blind'!AA38="PASS"),"PA",TRUE,"FA")} -> PA
A45: N/A | C45: N/A | E45: EV5.5.8/14 | G45: EV5.5.8 TSAC attachments | O45: See Layup SIS floor and ACP
A46: N/A | C46: N/A | E46: T1.2.1/T4.8 | G46: Firewall | O46: Aramide 158 tex/Epoxy resin SR 1126/0,5mm Alu | T46: =IF('T1.2.1 T4.6 T4.8 Firewall'!D3="PASS","PA","FA") -> PA
A47: =IF(NOT('EV5.5.1&2 EV4.4 ACPS TSPS Side'!F2="tubing only"),"NO",IF('EV5.5.1&2 EV4.4 ACPS TSPS Side'!G17="YES","YES","NO")) -> NO | C47: =IF(A47="N/A","N/A",IF(A47="YES","NO","YES")) -> YES | E47: EV4.4/EV5.5 | G47: =IF(D17="electric vehicle","Accumulator&Tractive System Protection Side","N/A") -> Accumulator&Tractive System Protection Side | O47: See SIS Side layup | T47: =IF($A$47="NO",'EV5.5.1&2 EV4.4 ACPS TSPS Side'!$L$27,"NA") -> 134.10134 | U47: =IF($A$47="NO",'EV5.5.1&2 EV4.4 ACPS TSPS Side'!$L$28,"NA") -> NA | V47: =IF($A$47="NO",'EV5.5.1&2 EV4.4 ACPS TSPS Side'!$L$29,"NA") -> NA | W47: =IF($A$47="NO",'EV5.5.1&2 EV4.4 ACPS TSPS Side'!$L$30,"NA") -> NA | X47: =IF($A$47="NO",'EV5.5.1&2 EV4.4 ACPS TSPS Side'!$L$31,"NA") -> NA | Y47: =IF($A$47="NO",'EV5.5.1&2 EV4.4 ACPS TSPS Side'!$L$32,"NA") -> NA | Z47: =IF($A$47="NO",'EV5.5.1&2 EV4.4 ACPS TSPS Side'!$L$33,"NA") -> NA | AA47: =IF($A$47="NO",'EV5.5.1&2 EV4.4 ACPS TSPS Side'!$L$34,"NA") -> NA | AB47: =IF($A$47="NO",'EV5.5.1&2 EV4.4 ACPS TSPS Side'!$L$35,"NA") -> NA | AC47: =IF('EV5.5.1&2 EV4.4 ACPS TSPS Side'!$F$2="tubing only",'EV5.5.1&2 EV4.4 ACPS TSPS Side'!$E$5,"") | AD47: =IF('EV5.5.1&2 EV4.4 ACPS TSPS Side'!$F$2="tubing only",'EV5.5.1&2 EV4.4 ACPS TSPS Side'!$E$6,"") | AE47: =IF('EV5.5.1&2 EV4.4 ACPS TSPS Side'!$F$2="tubing only",'EV5.5.1&2 EV4.4 ACPS TSPS Side'!$E$15,"") | AF47: =IF('EV5.5.1&2 EV4.4 ACPS TSPS Side'!$F$2="tubing only",'EV5.5.1&2 EV4.4 ACPS TSPS Side'!$E$16,"") | AG47: =IF('EV5.5.1&2 EV4.4 ACPS TSPS Side'!$F$2="tubing only",IF('EV5.5.1&2 EV4.4 ACPS TSPS Side'!$F$14>0,'EV5.5.1&2 EV4.4 ACPS TSPS Side'!$F$5,""),"") | AH47: =IF('EV5.5.1&2 EV4.4 ACPS TSPS Side'!$F$2="tubing only",IF('EV5.5.1&2 EV4.4 ACPS TSPS Side'!$F$14>0,'EV5.5.1&2 EV4.4 ACPS TSPS Side'!$F$6,""),"") | AI47: =IF('EV5.5.1&2 EV4.4 ACPS TSPS Side'!$F$2="tubing only",IF('EV5.5.1&2 EV4.4 ACPS TSPS Side'!$F$14>0,'EV5.5.1&2 EV4.4 ACPS TSPS Side'!$F$15,""),"") | AJ47: =IF('EV5.5.1&2 EV4.4 ACPS TSPS Side'!$F$2="tubing only",IF('EV5.5.1&2 EV4.4 ACPS TSPS Side'!$F$14>0,'EV5.5.1&2 EV4.4 ACPS TSPS Side'!$F$16,""),"") | AK47: =IF('EV5.5.1&2 EV4.4 ACPS TSPS Side'!$F$2="tubing only",IF('EV5.5.1&2 EV4.4 ACPS TSPS Side'!$G$14>0,'EV5.5.1&2 EV4.4 ACPS TSPS Side'!$G$5,""),"") | AL47: =IF('EV5.5.1&2 EV4.4 ACPS TSPS Side'!$F$2="tubing only",IF('EV5.5.1&2 EV4.4 ACPS TSPS Side'!$G$14>0,'EV5.5.1&2 EV4.4 ACPS TSPS Side'!$G$6,""),"") | AM47: =IF('EV5.5.1&2 EV4.4 ACPS TSPS Side'!$F$2="tubing only",IF('EV5.5.1&2 EV4.4 ACPS TSPS Side'!$G$14>0,'EV5.5.1&2 EV4.4 ACPS TSPS Side'!$G$15,""),"") | AN47: =IF('EV5.5.1&2 EV4.4 ACPS TSPS Side'!$F$2="tubing only",IF('EV5.5.1&2 EV4.4 ACPS TSPS Side'!$G$14>0,'EV5.5.1&2 EV4.4 ACPS TSPS Side'!$G$16,""),"") | AO47: =IF('EV5.5.1&2 EV4.4 ACPS TSPS Side'!$F$2="Tubing only","",'EV5.5.1&2 EV4.4 ACPS TSPS Side'!$I$5) -> Other 7 | AP47: =IF('EV5.5.1&2 EV4.4 ACPS TSPS Side'!$F$2="Tubing only","",'EV5.5.1&2 EV4.4 ACPS TSPS Side'!$I$18) -> 20.8 | AQ47: =IF('EV5.5.1&2 EV4.4 ACPS TSPS Side'!$F$2="Tubing only","",'EV5.5.1&2 EV4.4 ACPS TSPS Side'!$I$20) -> 1.4 | AR47: =IF('EV5.5.1&2 EV4.4 ACPS TSPS Side'!$F$2="Tubing only","",'EV5.5.1&2 EV4.4 ACPS TSPS Side'!$I$21) -> 1.4 | AS47: =IF('EV5.5.1&2 EV4.4 ACPS TSPS Side'!$F$2="Tubing only","",'EV5.5.1&2 EV4.4 ACPS TSPS Side'!$I$22) -> 273.4
A48: =IF(NOT('EV5.5.1&2 EV4.4 ACPS TSPS Rear'!F2="tubing only"),"NO",IF('EV5.5.1&2 EV4.4 ACPS TSPS Rear'!G17="YES","YES","NO")) -> NO | C48: =IF(A48="N/A","N/A",IF(A48="YES","NO","YES")) -> YES | E48: EV4.4/EV5.5 | G48: =IF(D17="electric vehicle","Accumulator&Tractive System Protection Rear","N/A") -> Accumulator&Tractive System Protection Rear | O48: Deltatech GG200T(M40J)-DT120-42 (fabric); Deltatech M40J-200-DT120-36; CP006; PAMG-XR1 5056 Aluminium Honeycomb 1/8"; 45f/-20M/0M/20M/0M/45f/0f/CP/18core/CP/0f/45f/0M/20M/0M/-20M/45f | T48: =IF($A$47="NO",'EV5.5.1&2 EV4.4 ACPS TSPS Rear'!$L$27,"NA") -> 117.20896 | U48: =IF($A$47="NO",'EV5.5.1&2 EV4.4 ACPS TSPS Rear'!$L$28,"NA") -> NA | V48: =IF($A$47="NO",'EV5.5.1&2 EV4.4 ACPS TSPS Rear'!$L$29,"NA") -> NA | W48: =IF($A$47="NO",'EV5.5.1&2 EV4.4 ACPS TSPS Rear'!$L$30,"NA") -> NA | X48: =IF($A$47="NO",'EV5.5.1&2 EV4.4 ACPS TSPS Rear'!$L$31,"NA") -> NA | Y48: =IF($A$47="NO",'EV5.5.1&2 EV4.4 ACPS TSPS Rear'!$L$32,"NA") -> NA | Z48: =IF($A$47="NO",'EV5.5.1&2 EV4.4 ACPS TSPS Rear'!$L$33,"NA") -> NA | AA48: =IF($A$47="NO",'EV5.5.1&2 EV4.4 ACPS TSPS Rear'!$L$34,"NA") -> NA | AB48: =IF($A$47="NO",'EV5.5.1&2 EV4.4 ACPS TSPS Rear'!$L$35,"NA") -> NA | AC48: =IF('EV5.5.1&2 EV4.4 ACPS TSPS Rear'!$F$2="tubing only",'EV5.5.1&2 EV4.4 ACPS TSPS Rear'!$E$5,"") | AD48: =IF('EV5.5.1&2 EV4.4 ACPS TSPS Rear'!$F$2="tubing only",'EV5.5.1&2 EV4.4 ACPS TSPS Rear'!$E$6,"") | AE48: =IF('EV5.5.1&2 EV4.4 ACPS TSPS Rear'!$F$2="tubing only",'EV5.5.1&2 EV4.4 ACPS TSPS Rear'!$E$15,"") | AF48: =IF('EV5.5.1&2 EV4.4 ACPS TSPS Rear'!$F$2="tubing only",'EV5.5.1&2 EV4.4 ACPS TSPS Rear'!$E$16,"") | AG48: =IF('EV5.5.1&2 EV4.4 ACPS TSPS Rear'!$F$2="tubing only",IF('EV5.5.1&2 EV4.4 ACPS TSPS Rear'!$F$14>0,'EV5.5.1&2 EV4.4 ACPS TSPS Rear'!$F$5,""),"") | AH48: =IF('EV5.5.1&2 EV4.4 ACPS TSPS Rear'!$F$2="tubing only",IF('EV5.5.1&2 EV4.4 ACPS TSPS Rear'!$F$14>0,'EV5.5.1&2 EV4.4 ACPS TSPS Rear'!$F$6,""),"") | AI48: =IF('EV5.5.1&2 EV4.4 ACPS TSPS Rear'!$F$2="tubing only",IF('EV5.5.1&2 EV4.4 ACPS TSPS Rear'!$F$14>0,'EV5.5.1&2 EV4.4 ACPS TSPS Rear'!$F$15,""),"") | AJ48: =IF('EV5.5.1&2 EV4.4 ACPS TSPS Rear'!$F$2="tubing only",IF('EV5.5.1&2 EV4.4 ACPS TSPS Rear'!$F$14>0,'EV5.5.1&2 EV4.4 ACPS TSPS Rear'!$F$16,""),"") | AK48: =IF('EV5.5.1&2 EV4.4 ACPS TSPS Rear'!$F$2="tubing only",IF('EV5.5.1&2 EV4.4 ACPS TSPS Rear'!$G$14>0,'EV5.5.1&2 EV4.4 ACPS TSPS Rear'!$G$5,""),"") | AL48: =IF('EV5.5.1&2 EV4.4 ACPS TSPS Rear'!$F$2="tubing only",IF('EV5.5.1&2 EV4.4 ACPS TSPS Rear'!$G$14>0,'EV5.5.1&2 EV4.4 ACPS TSPS Rear'!$G$6,""),"") | AM48: =IF('EV5.5.1&2 EV4.4 ACPS TSPS Rear'!$F$2="tubing only",IF('EV5.5.1&2 EV4.4 ACPS TSPS Rear'!$G$14>0,'EV5.5.1&2 EV4.4 ACPS TSPS Rear'!$G$15,""),"") | AN48: =IF('EV5.5.1&2 EV4.4 ACPS TSPS Rear'!$F$2="tubing only",IF('EV5.5.1&2 EV4.4 ACPS TSPS Rear'!$G$14>0,'EV5.5.1&2 EV4.4 ACPS TSPS Rear'!$G$16,""),"") | AO48: =IF('EV5.5.1&2 EV4.4 ACPS TSPS Rear'!$F$2="Tubing only","",'EV5.5.1&2 EV4.4 ACPS TSPS Rear'!$I$5) -> Other 8 | AP48: =IF('EV5.5.1&2 EV4.4 ACPS TSPS Rear'!$F$2="Tubing only","",'EV5.5.1&2 EV4.4 ACPS TSPS Rear'!$I$18) -> 22.7 | AQ48: =IF('EV5.5.1&2 EV4.4 ACPS TSPS Rear'!$F$2="Tubing only","",'EV5.5.1&2 EV4.4 ACPS TSPS Rear'!$I$20) -> 2.35 | AR48: =IF('EV5.5.1&2 EV4.4 ACPS TSPS Rear'!$F$2="Tubing only","",'EV5.5.1&2 EV4.4 ACPS TSPS Rear'!$I$21) -> 2.35 | AS48: =IF('EV5.5.1&2 EV4.4 ACPS TSPS Rear'!$F$2="Tubing only","",'EV5.5.1&2 EV4.4 ACPS TSPS Rear'!$I$22) -> 247.5
A49: Attachment Checklist (make sure all are included in your report)
A50: =IF(OR($T50="YES",$T50="N/A"),"P","F") -> P | B50: Receipt, data sheets or proof for Alternative Materials (T3.3) or for non-steel materials (composite, honeycomb, resin, etc) | T50: Yes
A51: =IF(OR($T51="YES",$T51="N/A"),"P","F") -> P | B51: Properties for all non-steel materials | T51: Yes
A52: =IF(OR($T52="YES",$T52="N/A"),"P","F") -> P | B52: Monocoque Laminate Test data and pictures | T52: Yes
A53: =IF(OR($T53="YES",$T53="N/A"),"P","F") -> P | B53: Holes >4mm drilled in any regulated tubing require proof of equivalency, include area and moment of inertia | T53: N/A
...

Sheet Chassis Pics
A1: =CONCATENATE(Read_Me!A1," FS STRUCTURAL EQUIVALENCY SPREADSHEET (SES) ",Read_Me!B1," - COVER SHEET") -> 2026 FS STRUCTURAL EQUIVALENCY SPREADSHEET (SES) V1.3 - COVER SHEET
V2: This chart below is for laminated members of the primary structure, ACPS and TSPS only!
A3: University Name | D3: =IF('Cover Sheet'!D14:J14>0,'Cover Sheet'!D14:J14,"") -> OTH Amberg-Weiden | K3: Car No.(s) & Event(s) | O3: =IF('Cover Sheet'!O14:S14>0,'Cover Sheet'!O14:S14,"") -> FSA E32; FSG 23; FSP E23 | V3: Structure | W3: Thickness outer skin [mm] | X3: Core thickness [mm] | Y3: Thickness inner skin [mm]
A5: Please attach pictures of the frame and/or monocoque in the table below for review during the SES process. All tubes/lay-ups must be colour coded to show outer diameter and wall thickness. Three view drawings and isometric views of the structure (CAD, FEA models, etc) are acceptable. Note: Identical composite layups need the identical colour code beyond borders of their specific lamiante structure! Maybe you need to work with two picture sets (Structures & your design)
V8: MHBS | W8: ='T3.11.5 T3.6 MHoop Brace Spt'!$F$21 -> 1 | X8: ='T3.11.5 T3.6 MHoop Brace Spt'!$F$19 -> 18 | Y8: ='T3.11.5 T3.6 MHoop Brace Spt'!$F$20 -> 1
V9: FHB | W9: ='T3.12 T3.6 FHoop Bracing'!$F$21 -> 1.4 | X9: ='T3.12 T3.6 FHoop Bracing'!$F$19 -> 18 | Y9: ='T3.12 T3.6 FHoop Bracing'!$F$20 -> 1.4
A10: Images must include dimensions/labels indicating the following: | R10: Compliance shown? | V10: FBH | W10: ='T3.13 T3.6 Ft Bulkhead'!$F$24 -> 2.75 | X10: ='T3.13 T3.6 Ft Bulkhead'!$F$22 -> 18 | Y10: ='T3.13 T3.6 Ft Bulkhead'!$F$23 -> 2.75
V11: FBHS | W11: ='T3.14 T3.6 FBH Spt Structure'!$I$21 -> 1.4 | X11: ='T3.14 T3.6 FBH Spt Structure'!$I$19 -> 18 | Y11: ='T3.14 T3.6 FBH Spt Structure'!$I$20 -> 1.4
A12: Angle of main and front hoops, including angle of main hoop below upper side impact tube. | R12: Yes | V12: SIS vertical | W12: ='T3.15 T3.6 SIS'!$I$21 -> 1.4 | X12: ='T3.15 T3.6 SIS'!$I$19 -> 18 | Y12: ='T3.15 T3.6 SIS'!$I$20 -> 1.4
A13: Angle between main hoop bracing and main hoop | R13: Yes | V13: SIS horizontal | W13: ='T3.15 T3.6 SIS'!$J$21 -> 1.15 | X13: ='T3.15 T3.6 SIS'!$J$19 -> 10 | Y13: ='T3.15 T3.6 SIS'!$J$20 -> 1.15
A14: Distance from top of main hoop to main hoop brace attachment | R14: Yes | V14: SHB | W14: ='T5.5 Shoulder Harness Bar'!$F$23 -> 1 | X14: ='T5.5 Shoulder Harness Bar'!$F$21 -> 18 | Y14: ='T5.5 Shoulder Harness Bar'!$F$22 -> 1
A15: Distance from top of front hoop to front hoop brace attachment | R15: Yes | U15: pink | V15: TSPS | W15: 1.4 | X15: 18 | Y15: 1.4
A16: Outer diameter and wall thickness of all tubes / monocoque lay-up | R16: Yes | U16: blue | V16: ACPS | W16: 2.35 | X16: 18 | Y16: 2.35
A17: Compliance to T 7.3.1 - Protection of lubrication systems | R17: Yes | U17: grey | V17: TSPS Floor | W17: 0.85 | X17: 10 | Y17: 0.85
A18: Distance between front hoop braces (measured at front hoop) | R18: Yes | U18: lght pink | V18: Non SES | W18: 1 | X18: 18 | Y18: 1
A19: Teams entering cars with IC Powertrains must show the location of the fuel tank and complete filler neck inside rollover protection structure (CV2.2.2) in all images and highlight them in the colour red. | R19: N/A | V19: YourMaterial11
A20: Teams entering cars with EV Powertrains must show the location of all HV components in these images and highlight them by colouring them orange. | R20: Yes | V20: YourMaterial12
A21: Teams with breakthroughs/cutouts/holes in the laminated primary structure greater 60 mm² must show their location in these images and highlight them by colouring them purple. These breakthroughs/cutouts/holes must also be shown in the SE3D-file. | R21: Yes | V21: YourMaterial13
V22: YourMaterial14
L50: SIS Side, TSPS Side have the same layup
L51: MHBS and SHB have the same layup
B55: Areas on the monococque with the same layup
U58: We do not have any lubrication system below the line between the lowest point of the main hoop and the lowst chassis member
U59: We do not have a FH Attachment because it is laminated into the monocoque.

Sheet A2.2 First year vehicle
A1: Note that the requirements on whether a vehicle can be called 'new' have been updated (see A2.2.2 & A2.2.3)!
A2: Please select chassis type: | B2: A2.2.2 - First year vehicle
A4: First day onsite of first competition (past/future): | B4: 46229
A6: Exemption under: | B6: N/A
A8: =IF($B$2="A2.2.2 - First year vehicle", "Provide proof of newly manufactured chassis, e.g. by explaining and providing images of considerable changes to your current chassis vs. its predecessor or providing pictures of old vs. newly manufactured chassis (side by side, physically).", "Show picture of existing chassis, provide clarity on, if applicable, required changes and current state of chassis") -> Provide proof of newly manufactured chassis, e.g. by explaining and providing images of considerable changes to your current chassis vs. its predecessor or providing pictures of old vs. newly manufactured chassis (side by side, physically).
A11: New materials | B11: New materials can be seen in tab Chassis Pics
A12: New layup | B12: Due to using new materials a new layup structure was necessary
A15: Old Chassis
A32: New Chassis

Sheet MaterialData
B1: Material Data Sheet
B3: Material Spreadsheet Code | C3: Steel | D3: Steel 2 | E3: Aluminium 1 | F3: Aluminium 2 | G3: Composite 1 | H3: Other 1 | I3: Other 2 | J3: Other 3 | K3: Other 4 | L3: Other 5 | M3: Other 6 | N3: Other 7 | O3: Other 8 | P3: Other 9 | Q3: Other 10 | R3: Other 11 | S3: Other 12 | T3: Other 13 | U3: Other 14 | V3: Other 15
B4: Material name | C4: Steel | D4: Lower Grade Steel | E4: Aluminium 1 | F4: Aluminium 2 | G4: vertical SIS | H4: FBHS | I4: FBH | J4: SIS hor. | K4: MHBS Mid/low | L4: SHB | M4: FHB | N4: TSPS | O4: ACPS | P4: TSPS Floor | Q4: MH upper Attachment | R4: Non SES | T4: Your Mat.13 | U4: Your Mat.14 | V4: Your Mat.15
B5: Colour in Chassis Pics | N5: pink | O5: blue | P5: grey | Q5: dark blue | R5: light pink
B6: Youngs Modulus, E | C6: 200000000000 | D6: 1 | E6: 70000000000 | F6: 74870000000 | G6: ='T3.6 Laminate Tests'!BD57*1000000000 -> 7.0222605e+10 | H6: ='T3.6 Laminate Tests'!CA57*1000000000 -> 9.03084e+10 | I6: ='T3.6 Laminate Tests'!CU57*1000000000 -> 2.8812008e+10 | J6: ='T3.6 Laminate Tests'!DO57*1000000000 -> 1.1745457e+11 | K6: ='T3.6 Laminate Tests'!EI57*1000000000 -> 1.2365853e+11 | L6: ='T3.6 Laminate Tests'!HK57*1000000000 -> 1.0372044e+11 | M6: ='T3.6 Laminate Tests'!HK57*1000000000 -> 1.0372044e+11 | N6: ='T3.6 Laminate Tests'!FC57*1000000000 -> 7.0222605e+10 | O6: ='T3.6 Laminate Tests'!GQ57*1000000000 -> 3.475518e+10 | P6: ='T3.6 Laminate Tests'!FW57*1000000000 -> 2.1574936e+11 | Q6: 11 | R6: ='T3.6 Laminate Tests'!IY57*1000000000 -> 6.1576083e+10 | S6: 12 | T6: 10 | U6: 11 | V6: 12
B7: Yield strength, Pa | C7: 305000000 | D7: 1 | E7: 160000000 | F7: 280000000 | G7: =G8 -> 2.8784551e+08 | H7: =H8 -> 3.6781081e+08 | I7: =I8 -> 1.865214e+08 | J7: =J8 -> 4.7369603e+08 | K7: =K8 -> 4.8114344e+08 | L7: =L8 -> 3.5364777e+08 | M7: =M8 -> 3.7799075e+08 | N7: =N8 -> 2.8784551e+08 | ... R7: =R8 -> 2.6177793e+08 | S7: 12 | T7: 10 | U7: 11 | V7: 12
B8: UTS, Pa | C8: 365000000 | D8: 1 | E8: 300000000 | F8: 350000000 | G8: ='T3.6 Laminate Tests'!BD58*1000000 -> 2.8784551e+08 | H8: ='T3.6 Laminate Tests'!CA58*1000000 -> 3.6781081e+08 | I8: ='T3.6 Laminate Tests'!CU58*1000000 -> 1.865214e+08 | J8: ='T3.6 Laminate Tests'!DO58*1000000 -> 4.7369603e+08 | K8: ='T3.6 Laminate Tests'!EI58*1000000 -> 4.8114344e+08 | L8: ='T3.6 Laminate Tests'!HK58*1000000 -> 3.5364777e+08 | M8: ='T3.6 Laminate Tests'!IE58*1000000 -> 3.7799075e+08 | N8: ='T3.6 Laminate Tests'!FC58*1000000 -> 2.8784551e+08 | O8: ='T3.6 Laminate Tests'!GQ58*1000000 -> 2.1959888e+08 | P8: ='T3.6 Laminate Tests'!FW58*1000000 -> 9.2097321e+08 | Q8: ='T3.6.10 Shear Tests'!GV54*1000000 -> 2.5660535e+08 | R8: ='T3.6 Laminate Tests'!IY58*1000000 -> 2.6177793e+08 | S8: 12 | T8: 10 | U8: 11 | V8: 12
B9: Yield strength, welded, Pa | C9: 180000000 | D9: 1 | E9: 140000000 | F9: 142205333 | G9: N/A | H9: N/A | I9: N/A | J9: N/A | K9: N/A | L9: N/A | M9: N/A | N9: N/A | O9: N/A | P9: N/A | Q9: N/A | R9: N/A | S9: N/A | T9: N/A | U9: N/A | V9: N/A
B10: UTS welded, Pa | C10: 300000000 | D10: 1 | E10: 300000000 | F10: 194416580 | G10: N/A | H10: N/A | I10: N/A | J10: N/A | K10: N/A | L10: N/A | M10: N/A | N10: N/A | O10: N/A | P10: N/A | Q10: N/A | R10: N/A | S10: N/A | T10: N/A | U10: N/A | V10: N/A
B11: UTS shear, Pa | C11: =0.6*C8 -> 219000000 | D11: 1 | E11: =39554/(PI()*25*3)*10^6 -> 1.6787239e+08 | F11: =39554/(PI()*25*3)*10^6 -> 1.6787239e+08 | G11: ='T3.6.10 Shear Tests'!D54*1000000 -> 92006407 | H11: ='T3.6.10 Shear Tests'!X54*1000000 -> 1.1711194e+08 | I11: ='T3.6.10 Shear Tests'!AR54*1000000 -> 1.2756193e+08 | J11: ='T3.6.10 Shear Tests'!BL54*1000000 -> 97495938 | K11: ='T3.6.10 Shear Tests'!CF54*1000000 -> 1.0581894e+08 | L11: ='T3.6.10 Shear Tests'!FH54*1000000 -> 1.7246577e+08 | M11: ='T3.6.10 Shear Tests'!GB54*1000000 -> 95344361 | N11: ='T3.6.10 Shear Tests'!CZ54*1000000 -> 1.177682e+08 | O11: ='T3.6.10 Shear Tests'!EN54*1000000 -> 1.3402797e+08 | P11: ='T3.6.10 Shear Tests'!DT54*1000000 -> 1.6098317e+08 | Q11: 10 | R11: ='T3.6.10 Shear Tests'!HP54*1000000 -> 79301688 | S11: 12 | T11: 10 | U11: 11 | V11: 12
C13: ● Steel properties based on baseline steel and are given in Rule T3.2.4.
C14: ● Results from extra physical test required by T3.5 should be entered in the "Other x" materials column as required.
C15: ● If you are using TAB “T3.5 Different Layups” to create different/multiple composite layups other than your SIS-Layup from TAB “T3.5 Laminate Test”,
C16: you must fill out manually the columns at “Other X” in this Material Data Sheet TAB.
H20: Please use the following abbreviations for your specific lamiante structure (Other "X")
I21: Front Bulkhead -> FBH
I22: Front Bulkhead Support -> FBHS
B23: Tubing only | I23: Front Hoop Bracing -> FHB
B24: Composite only | I24: Main Hoop Bracing Support -> MHBS
B25: Tubes + composite | I25: Shoulder Harness Bar -> SHB
I26: Accumulator Container Protection Structure -> ACPS
B27: Round | I27: Tractive System Protection Structure -> TSPS
B28: Square

Sheet Metal Datasheets
A1: =CONCATENATE(Read_Me!A1," FS SES ",Read_Me!B1," - Datasheets Metal") -> 2026 FS SES V1.3 - Datasheets Metal
R2: BACK to COVER SHEET
A3: University Name | D3: =IF('Cover Sheet'!$D$14>0,'Cover Sheet'!$D$14,"") -> OTH Amberg-Weiden | I3: Car No.(s) & Event(s) | M3: =IF('Cover Sheet'!$O$14>0,'Cover Sheet'!$O$14,"") -> FSA E32; FSG 23; FSP E23
A5: Aluminum 1 | R5: ="Tensile Test - NORMAL CONDITION - "&A5 -> Tensile Test - NORMAL CONDITION - Aluminum 1 | AI5: ="Tensile Test - WELDED CONDITION - "&A5 -> Tensile Test - WELDED CONDITION - Aluminum 1 | AZ5: Aluminum 2 | BQ5: ="Tensile Test - NORMAL CONDITION - "&AZ5 -> Tensile Test - NORMAL CONDITION - Aluminum 2 | CH5: ="Tensile Test - WELDED CONDITION - "&AZ5 -> Tensile Test - WELDED CONDITION - Aluminum 2 | CY5: Main hoop tube and main hoop bracing tube; steel | DP5: ="Tensile Test - NORMAL CONDITION - "&CY5 -> Tensile Test - NORMAL CONDITION - Main hoop tube and main hoop bracing tube; steel | EG5: ="Tensile Test - WELDED CONDITION - "&CY5 -> Tensile Test - WELDED CONDITION - Main hoop tube and main hoop bracing tube; steel
A7: Material Type | I7: Aluminium | R7: Diagram Area | AI7: Diagram Area | AZ7: Material Type | BH7: Aluminium | BQ7: Diagram Area | CH7: Diagram Area | CY7: Material Type | DG7: Steel | DP7: Diagram Area | EG7: Diagram Area
A9: T 3.2.2 / T 3.2.4 baseline steel? | I9: No | AZ9: T 3.2.2 / T 3.2.4 baseline steel? | BH9: Yes | CY9: T 3.2.2 / T 3.2.4 baseline steel? | DG9: Yes
A11: Max. Element Content [%] | I11: =IF(OR(A13>0.3,C13>1.7,F13>0.6,I9="No"),"Not Baseline", "Baseline Composition") -> Not Baseline | AZ11: Max. Element Content [%] | BH11: =IF(OR(AZ13>0.3,BB13>1.7,BE13>0.6,BH9="No"),"Not Baseline", "Baseline Composition") -> Baseline Composition | CY11: Max. Element Content [%] | DG11: =IF(OR(CY13>0.3,DA13>1.7,DD13>0.6,DG9="No"),"Not Baseline", "Baseline Composition") -> Baseline Composition
A12: Carbon(C) | C12: Manganese(Mn) | F12: Other Element | AZ12: Carbon(C) | BB12: Manganese(Mn) | BE12: Other Element | CY12: Carbon(C) | DA12: Manganese(Mn) | DD12: Other Element
A13: 0.3 | C13: 1.7 | F13: 0.6 | AZ13: 0.3 | BB13: 1.7 | BE13: 0.6 | CY13: 0.3 | DA13: 1.7 | DD13: 0.6
A14: Yield Strength [N/mm²] Normal | I14: 305 | AZ14: Yield Strength [N/mm²] Normal | BH14: 305 | CY14: Yield Strength [N/mm²] Normal | DG14: 305
A16: Tensile Strength (UTS) [N/mm²] Normal | I16: 365 | AZ16: Tensile Strength (UTS) [N/mm²] Normal | BH16: 365 | CY16: Tensile Strength (UTS) [N/mm²] Normal | DG16: 365
